<?xml version="1.0" ?>
<!-- =================================================================================== -->
<!-- |    This document was autogenerated by xacro from irb120.xacro                   | -->
<!-- |    EDITING THIS FILE BY HAND IS NOT RECOMMENDED                                 | -->
<!-- =================================================================================== -->
<robot name="abb_irb120" xmlns:xacro="http://ros.org/wiki/xacro">
  <!-- Conversion were obtained from http://www.e-paint.co.uk/Lab_values.asp
       unless otherwise stated. -->
  <!-- Actual colors -->
  <!-- NCS 2070-Y60R orange, standard robot color 1974 - May 2014 -->
  <!-- RAL 7035 light grey (abb graphite white), standard robot color May 2014 - current -->
  <!-- RAL 9003 signal white (abb white), cleanroom robot color -->
  <!-- RAL 7032 pebble gray, controller -->
  <!-- RAL 7012 basalt gray (abb dark gray) , robot primer -->
  <!-- RAL 7021 black gray (abb black) , robot with dark link color -->
  <!-- Other robot colours availble, but not limited too. -->
  <!-- RAL 3001 signal red -->
  <!-- RAL 3002 carmine red -->
  <!-- RAL 5002 ultramarine blue -->
  <!-- RAL 5015 sky blue -->
  <!-- RAL 6002 leaf green -->
  <!-- RAL 9002 gray white -->
  <!-- RAL 9010 pure white -->
  <!-- approximations -->
  <!-- yellow, collision model -->
  <!-- link list -->
  <link name="base_link">
    <inertial>
      <mass value="6.215"/>
      <origin rpy="0 0 0" xyz="-0.04204 8.01E-05 0.07964"/>
      <inertia ixx="0.0247272" ixy="-8.0784E-05" ixz="0.00130902" iyy="0.0491285" iyz="-8.0419E-06" izz="0.0472376"/>
    </inertial>
    <visual>
      <origin rpy="0 0 0" xyz="0 0 0"/>
      <geometry>
        <mesh filename="package://urdf_irb120_bhand/meshes/irb120/visual/base_link.stl"/>
      </geometry>
      <material name="">
        <color rgba="0.7725490 0.7803922 0.7686275 1"/>
      </material>
    </visual>
    <collision>
      <origin rpy="0 0 0" xyz="0 0 0"/>
      <geometry>
        <mesh filename="package://urdf_irb120_bhand/meshes/irb120/collision/base_link.stl"/>
      </geometry>
      <material name="">
        <color rgba="1 1 0 1"/>
      </material>
    </collision>
  </link>
  <link name="link_1">
    <inertial>
      <mass value="3.067"/>
      <origin rpy="0 0 0" xyz="9.77E-05 -0.00012 0.23841"/>
      <inertia ixx="0.0142175" ixy="-1.28579E-05" ixz="-2.31364E-05" iyy="0.0144041" iyz="1.93404E-05" izz="0.0104533"/>
    </inertial>
    <visual>
      <origin rpy="0 0 0" xyz="0 0 0"/>
      <geometry>
        <mesh filename="package://urdf_irb120_bhand/meshes/irb120/visual/link_1.stl"/>
      </geometry>
      <material name="">
        <color rgba="0.7725490 0.7803922 0.7686275 1"/>
      </material>
    </visual>
    <collision>
      <origin rpy="0 0 0" xyz="0 0 0"/>
      <geometry>
        <mesh filename="package://urdf_irb120_bhand/meshes/irb120/collision/link_1.stl"/>
      </geometry>
      <material name="">
        <color rgba="1 1 0 1"/>
      </material>
    </collision>
  </link>
  <link name="link_2">
    <inertial>
      <mass value="3.909"/>
      <origin rpy="0 0 0" xyz="0.00078 -0.00212 0.10124"/>
      <inertia ixx="0.0603111" ixy="9.83431E-06" ixz="5.72407E-05" iyy="0.041569" iyz="-0.00050497" izz="0.0259548"/>
    </inertial>
    <visual>
      <origin rpy="0 0 0" xyz="0 0 0"/>
      <geometry>
        <mesh filename="package://urdf_irb120_bhand/meshes/irb120/visual/link_2.stl"/>
      </geometry>
      <material name="">
        <color rgba="0.7725490 0.7803922 0.7686275 1"/>
      </material>
    </visual>
    <collision>
      <origin rpy="0 0 0" xyz="0 0 0"/>
      <geometry>
        <mesh filename="package://urdf_irb120_bhand/meshes/irb120/collision/link_2.stl"/>
      </geometry>
      <material name="">
        <color rgba="1 1 0 1"/>
      </material>
    </collision>
  </link>
  <link name="link_3">
    <inertial>
      <mass value="2.944"/>
      <origin rpy="0 0 0" xyz="0.02281 0.00106 0.05791"/>
      <inertia ixx="0.00835606" ixy="-8.01545E-05" ixz="0.00142884" iyy="0.016713" iyz="-0.000182227" izz="0.0126984"/>
    </inertial>
    <visual>
      <origin rpy="0 0 0" xyz="0 0 0"/>
      <geometry>
        <mesh filename="package://urdf_irb120_bhand/meshes/irb120/visual/link_3.stl"/>
      </geometry>
      <material name="">
        <color rgba="0.7725490 0.7803922 0.7686275 1"/>
      </material>
    </visual>
    <collision>
      <origin rpy="0 0 0" xyz="0 0 0"/>
      <geometry>
        <mesh filename="package://urdf_irb120_bhand/meshes/irb120/collision/link_3.stl"/>
      </geometry>
      <material name="">
        <color rgba="1 1 0 1"/>
      </material>
    </collision>
  </link>
  <link name="link_4">
    <inertial>
      <mass value="1.328"/>
      <origin rpy="0 0 0" xyz="0.2247 0.00015 0.00041"/>
      <inertia ixx="0.00284661" ixy="-2.12765E-05" ixz="-1.6435E-05" iyy="0.00401346" iyz="1.31336E-05" izz="0.0052535"/>
    </inertial>
    <visual>
      <origin rpy="0 0 0" xyz="0 0 0"/>
      <geometry>
        <mesh filename="package://urdf_irb120_bhand/meshes/irb120/visual/link_4.stl"/>
      </geometry>
      <material name="">
        <color rgba="0.7725490 0.7803922 0.7686275 1"/>
      </material>
    </visual>
    <collision>
      <origin rpy="0 0 0" xyz="0 0 0"/>
      <geometry>
        <mesh filename="package://urdf_irb120_bhand/meshes/irb120/collision/link_4.stl"/>
      </geometry>
      <material name="">
        <color rgba="1 1 0 1"/>
      </material>
    </collision>
  </link>
  <link name="link_5">
    <inertial>
      <mass value="0.546"/>
      <origin rpy="0 0 0" xyz="-0.00109 3.68E-05 6.22E-05"/>
      <inertia ixx="0.000404891" ixy="1.61943E-06" ixz="8.46805E-07" iyy="0.000892825" iyz="-1.51792E-08" izz="0.000815468"/>
    </inertial>
    <visual>
      <origin rpy="0 0 0" xyz="0 0 0"/>
      <geometry>
        <mesh filename="package://urdf_irb120_bhand/meshes/irb120/visual/link_5.stl"/>
      </geometry>
      <material name="">
        <color rgba="0.7725490 0.7803922 0.7686275 1"/>
      </material>
    </visual>
    <collision>
      <origin rpy="0 0 0" xyz="0 0 0"/>
      <geometry>
        <mesh filename="package://urdf_irb120_bhand/meshes/irb120/collision/link_5.stl"/>
      </geometry>
      <material name="">
        <color rgba="1 1 0 1"/>
      </material>
    </collision>
  </link>
  <link name="link_6">
    <inertial>
      <mass value="0.137"/>
      <origin rpy="0 0 0" xyz="-0.00706 -0.00017 -1.32E-06"/>
      <inertia ixx="0.001" ixy="0" ixz="0" iyy="0.001" iyz="0" izz="0.001"/>
    </inertial>
    <visual>
      <origin rpy="0 0 0" xyz="0 0 0"/>
      <geometry>
        <mesh filename="package://urdf_irb120_bhand/meshes/irb120/visual/link_6.stl"/>
      </geometry>
      <material name="">
        <color rgba="0.1882353 0.1960784 0.2039216 1"/>
      </material>
    </visual>
    <collision>
      <origin rpy="0 0 0" xyz="0 0 0"/>
      <geometry>
        <mesh filename="package://urdf_irb120_bhand/meshes/irb120/collision/link_6.stl"/>
      </geometry>
      <material name="">
        <color rgba="1 1 0 1"/>
      </material>
    </collision>
  </link>



  <link
    name="base_link_BH">
    <inertial>
      <origin
        xyz="-1.53444878605399E-05 -0.00277693660903533 0.0352882290973172"
        
        rpy="0 0 0" />
      <mass
        value="0.377966381303299" />
      <inertia
        ixx="0.000427326373018601"
        ixy="2.6443337984506E-07"
        ixz="-2.02908063714989E-07"
        iyy="0.000361316175967098"
        iyz="-3.0792687327603E-05"
        izz="0.000376798128588446" />
    </inertial>
    <visual>
      <origin
        xyz="0 0 0"
        rpy="0 0 0" />
      <geometry>
        <mesh
          filename="package://urdf_irb120_bhand/meshes/BH4851/base_link.STL" />
      </geometry>
      <material
        name="">
        <color
          rgba="0.752941176470588 0.752941176470588 0.752941176470588 1" />
      </material>
    </visual>
    <collision>
      <origin
        xyz="0 0 0"
        rpy="0 0 0" />
      <geometry>
        <mesh
          filename="package://urdf_irb120_bhand/meshes/BH4851/base_link.STL" />
      </geometry>
    </collision>
  </link>


  <link
    name="finger_1_prox_link">
    <inertial>
      <origin
        xyz="-0.0288648917008988 9.98379746692153E-05 0.0171253477569802"
        rpy="0 0 0" />
      <mass
        value="56143.0626955765" />
      <inertia
        ixx="10.4484040652085"
        ixy="-0.117861448219975"
        ixz="-5.31613760585343"
        iyy="33.9552353012776"
        iyz="0.0780041192837706"
        izz="29.3669090518615" />
    </inertial>
    <visual>
      <origin
        xyz="0 0 0"
        rpy="0 0 0" />
      <geometry>
        <mesh
          filename="package://urdf_irb120_bhand/meshes/BH4851/finger_1_prox_link.STL" />
      </geometry>
      <material
        name="">
        <color
          rgba="0.752941176470588 0.752941176470588 0.752941176470588 1" />
      </material>
    </visual>
    <collision>
      <origin
        xyz="0 0 0"
        rpy="0 0 0" />
      <geometry>
        <mesh
          filename="package://urdf_irb120_bhand/meshes/BH4851/finger_1_prox_link.STL" />
      </geometry>
    </collision>
  </link>
 

  <link
    name="finger_1_med_liink">
    <inertial>
      <origin
        xyz="-0.030918176135544 0.0019693024932544 0.000743369842666108"
        rpy="0 0 0" />
      <mass
        value="31321.1214212939" />
      <inertia
        ixx="2.18512832127284"
        ixy="-0.844484268309696"
        ixz="0.0135401272401385"
        iyy="17.3596441998536"
        iyz="-0.001126692167519"
        izz="17.7656644395659" />
    </inertial>
    <visual>
      <origin
        xyz="0 0 0"
        rpy="0 0 0" />
      <geometry>
        <mesh
          filename="package://urdf_irb120_bhand/meshes/BH4851/finger_1_med_liink.STL" />
      </geometry>
      <material
        name="">
        <color
          rgba="0.752941176470588 0.752941176470588 0.752941176470588 1" />
      </material>
    </visual>
    <collision>
      <origin
        xyz="0 0 0"
        rpy="0 0 0" />
      <geometry>
        <mesh
          filename="package://urdf_irb120_bhand/meshes/BH4851/finger_1_med_liink.STL" />
      </geometry>
    </collision>
  </link>



  <link
    name="finger_1_dist_link">
    <inertial>
      <origin
        xyz="-0.018331495851456 0.017563370050582 0.000497127783315291"
        rpy="0 0 0" />
      <mass
        value="19342.3312257343" />
      <inertia
        ixx="3.67466110522623"
        ixy="-2.57800680786605"
        ixz="-0.0345727635031181"
        iyy="4.08727012680705"
        iyz="0.0329223427372985"
        izz="5.99395386650428" />
    </inertial>
    <visual>
      <origin
        xyz="0 0 0"
        rpy="0 0 0" />
      <geometry>
        <mesh
          filename="package://urdf_irb120_bhand/meshes/BH4851/finger_1_dist_link.STL" />
      </geometry>
      <material
        name="">
        <color
          rgba="0.898039215686275 0.917647058823529 0.929411764705882 1" />
      </material>
    </visual>
    <collision>
      <origin
        xyz="0 0 0"
        rpy="0 0 0" />
      <geometry>
        <mesh
          filename="package://urdf_irb120_bhand/meshes/BH4851/finger_1_dist_link.STL" />
      </geometry>
    </collision>
  </link>
  
  <link
    name="finger_2_prox_link">
    <inertial>
      <origin
        xyz="-0.0288648917008987 9.98379746692118E-05 0.0171253477569802"
        rpy="0 0 0" />
      <mass
        value="56143.0626955765" />
      <inertia
        ixx="10.4484040652085"
        ixy="-0.117861448219975"
        ixz="-5.31613760585343"
        iyy="33.9552353012776"
        iyz="0.0780041192837701"
        izz="29.3669090518615" />
    </inertial>
    <visual>
      <origin
        xyz="0 0 0"
        rpy="0 0 0" />
      <geometry>
        <mesh
          filename="package://urdf_irb120_bhand/meshes/BH4851/finger_2_prox_link.STL" />
      </geometry>
      <material
        name="">
        <color
          rgba="0.752941176470588 0.752941176470588 0.752941176470588 1" />
      </material>
    </visual>
    <collision>
      <origin
        xyz="0 0 0"
        rpy="0 0 0" />
      <geometry>
        <mesh
          filename="package://urdf_irb120_bhand/meshes/BH4851/finger_2_prox_link.STL" />
      </geometry>
    </collision>
  </link>
  
  <link
    name="finger_2_med_link">
    <inertial>
      <origin
        xyz="-0.0309061378225848 0.00214997948654991 0.000743369814045599"
        rpy="0 0 0" />
      <mass
        value="31321.1215499126" />
      <inertia
        ixx="2.19551825824831"
        ixy="-0.933117181988174"
        ixz="0.0135333166873642"
        iyy="17.3492542935561"
        iyz="-0.00120585854514789"
        izz="17.7656644132238" />
    </inertial>
    <visual>
      <origin
        xyz="0 0 0"
        rpy="0 0 0" />
      <geometry>
        <mesh
          filename="package://urdf_irb120_bhand/meshes/BH4851/finger_2_med_link.STL" />
      </geometry>
      <material
        name="">
        <color
          rgba="0.752941176470588 0.752941176470588 0.752941176470588 1" />
      </material>
    </visual>
    <collision>
      <origin
        xyz="0 0 0"

        rpy="0 0 0" />
      <geometry>
        <mesh
          filename="package://urdf_irb120_bhand/meshes/BH4851/finger_2_med_link.STL" />
      </geometry>
    </collision>
  </link>
  
  <link
    name="finger_2_dist_link">
    <inertial>
      <origin
        xyz="-0.0181940669984822 0.017705695005231 0.000497127783261171"
        rpy="0 0 0" />
      <mass
        value="19342.3313295693" />
      <inertia
        ixx="3.71486604025429"
        ixy="-2.58090906930852"
        ixz="-0.0343151446338957"
        iyy="4.04706522522361"
        iyz="0.0331907761165059"
        izz="5.99395390717116" />
    </inertial>
    <visual>
      <origin
        xyz="0 0 0"
        rpy="0 0 0" />
      <geometry>
        <mesh
          filename="package://urdf_irb120_bhand/meshes/BH4851/finger_2_dist_link.STL" />
      </geometry>
      <material
        name="">
        <color
          rgba="0.898039215686275 0.917647058823529 0.929411764705882 1" />
      </material>
    </visual>
    <collision>
      <origin
        xyz="0 0 0"
        rpy="0 0 0" />
      <geometry>
        <mesh
          filename="package://urdf_irb120_bhand/meshes/BH4851/finger_2_dist_link.STL" />
      </geometry>
    </collision>
  </link>
  
  <link
    name="finger_3_med_link">
    <inertial>
      <origin
        xyz="-0.0309181761355441 0.00196930249325443 0.000743369842666415"
        rpy="0 0 0" />
      <mass
        value="31321.121421294" />
      <inertia
        ixx="2.18512832127284"
        ixy="-0.844484268309696"
        ixz="0.0135401272400822"
        iyy="17.3596441998537"
        iyz="-0.0011266921675151"
        izz="17.7656644395659" />
    </inertial>
    <visual>
      <origin
        xyz="0 0 0"
        rpy="0 0 0" />
      <geometry>
        <mesh
          filename="package://urdf_irb120_bhand/meshes/BH4851/finger_3_med_link.STL" />
      </geometry>
      <material
        name="">
        <color
          rgba="0.752941176470588 0.752941176470588 0.752941176470588 1" />
      </material>
    </visual>
    <collision>
      <origin
        xyz="0 0 0"
        rpy="0 0 0" />
      <geometry>
        <mesh
          filename="package://urdf_irb120_bhand/meshes/BH4851/finger_3_med_link.STL" />
      </geometry>
    </collision>
  </link>
  
  <link
    name="finger_3_dist_link">
    <inertial>
      <origin
        xyz="-0.0183314958518909 0.0175633700501297 0.000497127783323787"
        rpy="0 0 0" />
      <mass
        value="19342.3312257343" />
      <inertia
        ixx="3.67466110509902"
        ixy="-2.57800680785588"
        ixz="-0.0345727635040649"
        iyy="4.08727012693427"
        iyz="0.0329223427365976"
        izz="5.99395386650428" />
    </inertial>
    <visual>
      <origin
        xyz="0 0 0"
        rpy="0 0 0" />
      <geometry>
        <mesh
          filename="package://urdf_irb120_bhand/meshes/BH4851/finger_3_dist_link.STL" />
      </geometry>
      <material
        name="">
        <color
          rgba="0.898039215686275 0.917647058823529 0.929411764705882 1" />
      </material>
    </visual>
    <collision>
      <origin
        xyz="0 0 0"
        rpy="0 0 0" />
      <geometry>
        <mesh
          filename="package://urdf_irb120_bhand/meshes/BH4851/finger_3_dist_link.STL" />
      </geometry>
    </collision>
  </link>
  




  <!-- end of link list -->

	

  <!-- joint list -->
  <joint name="joint_1" type="revolute">
    <origin rpy="0 0 0" xyz="0 0 0"/>
    <parent link="base_link"/>
    <child link="link_1"/>
    <limit effort="0" lower="-2.87979" upper="2.87979" velocity="4.36332"/>
    <axis xyz="0 0 1"/>
    <dynamics damping="0.0" friction="0.0"/>
  </joint>
  <joint name="joint_2" type="revolute">
    <origin rpy="0 0 0" xyz="0 0 0.29"/>
    <parent link="link_1"/>
    <child link="link_2"/>
    <limit effort="0" lower="-1.91986" upper="1.91986" velocity="4.36332"/>
    <axis xyz="0 1 0"/>
    <dynamics damping="0.0" friction="0.0"/>
  </joint>
  <joint name="joint_3" type="revolute">
    <origin rpy="0 0 0" xyz="0 0 0.27"/>
    <parent link="link_2"/>
    <child link="link_3"/>
    <limit effort="0" lower="-1.91986" upper="1.22173" velocity="4.36332"/>
    <axis xyz="0 1 0"/>
    <dynamics damping="0.0" friction="0.0"/>
  </joint>
  <joint name="joint_4" type="revolute">
    <origin rpy="0 0 0" xyz="0 0 0.07"/>
    <parent link="link_3"/>
    <child link="link_4"/>
    <limit effort="0" lower="-2.79253" upper="2.79253" velocity="5.58505"/>
    <axis xyz="1 0 0"/>
    <dynamics damping="0.0" friction="0.0"/>
  </joint>
  <joint name="joint_5" type="revolute">
    <origin rpy="0 0 0" xyz="0.302 0 0"/>
    <parent link="link_4"/>
    <child link="link_5"/>
    <limit effort="0" lower="-2.094395" upper="2.094395" velocity="5.58505"/>
    <axis xyz="0 1 0"/>
    <dynamics damping="0.0" friction="0.0"/>
  </joint>
  <joint name="joint_6" type="revolute">
    <origin rpy="0 0 0" xyz="0.072 0 0"/>
    <parent link="link_5"/>
    <child link="link_6"/>
    <limit effort="0" lower="-6.98132" upper="6.98132" velocity="7.33038"/>
    <axis xyz="1 0 0"/>
    <dynamics damping="0.0" friction="0.0"/>
  </joint>
  
 
<joint name="joint6-tool0" type="fixed">
    <parent link="link_6"/>
    <child link="base_link_BH"/>
    <origin rpy="0 1.5708 0" xyz="0 0 0"/>
  </joint>


<joint
    name="finger_1_prox_joint"
    type="revolute">
    <origin
      xyz="0.025 0 0.0415"
      rpy="0 2.7051E-17 -1.5708" />
    <parent
      link="base_link_BH" />
    <child
      link="finger_1_prox_link" />
    <axis
      xyz="0 0 1" />
    <limit
      lower="-3.141"
      upper="0"
      effort="0"
      velocity="0" />
  </joint>

<joint
    name="finger_1_med_joint"
    type="revolute">
    <origin
      xyz="-0.05 0 0.0339"
      rpy="1.5708 -8.8281E-17 0" />
    <parent
      link="finger_1_prox_link" />
    <child
      link="finger_1_med_liink" />
    <axis
      xyz="0 0 1" />
    <limit
      lower="-2.44"
      upper="0"
      effort="0"
      velocity="0" />
  </joint>


<joint
    name="finger_1_dist_joint"
    type="revolute">
    <origin
      xyz="-0.069936 0.003 0"
      rpy="1.6787E-18 -3.6382E-15 -6.1073E-33" />
    <parent
      link="finger_1_med_liink" />
    <child
      link="finger_1_dist_link" />
    <axis
      xyz="0 0 1" />
    <limit
      lower="-0.785"
      upper="0"
      effort="0"
      velocity="0" />
<mimic joint="finger_1_med_joint" multiplier="0.3" offset="0.0"/>
  </joint>

<joint
    name="finger_2_prox_joint"
    type="revolute">
    <origin
      xyz="-0.025 0 0.0415"
      rpy="0 2.7051E-17 -1.5708" />
    <parent
      link="base_link_BH" />
    <child
      link="finger_2_prox_link" />
    <axis
      xyz="0 0 1" />
    <limit
      lower="0"
      upper="3.141"
      effort="0"
      velocity="0" />
<mimic joint="finger_1_prox_joint" multiplier="-1.0" offset="0.0"/>
  </joint>

<joint
    name="finger_2_med_joint"
    type="revolute">
    <origin
      xyz="-0.05 0 0.0339"
      rpy="1.5708 -8.8281E-17 0" />
    <parent
      link="finger_2_prox_link" />
    <child
      link="finger_2_med_link" />
    <axis
      xyz="0 0 1" />
    <limit
      lower="-2.44"
      upper="0"
      effort="0"
      velocity="0" />
  </joint>

<joint
    name="finger_2_dist_joint"
    type="revolute">
    <origin
      xyz="-0.069917 0.0034087 0"
      rpy="-3.1382E-17 -2.3229E-16 0" />
    <parent
      link="finger_2_med_link" />
    <child
      link="finger_2_dist_link" />
    <axis
      xyz="0 0 1" />
    <limit
      lower="-0.785"
      upper="0"
      effort="0"
      velocity="0" />
<mimic joint="finger_2_med_joint" multiplier="0.3" offset="0.0"/>
  </joint>

<joint
    name="finger_3_med_joint"
    type="revolute">
    <origin
      xyz="0 -0.05 0.0754"
      rpy="1.5708 6.123E-17 1.5708" />
    <parent
      link="base_link_BH" />
    <child
      link="finger_3_med_link" />
    <axis
      xyz="0 0 1" />
    <limit
      lower="-2.44"
      upper="0"
      effort="0"
      velocity="0" />
  </joint>

<joint
    name="finger_3_dist_joint"
    type="revolute">
    <origin
      xyz="-0.069936 0.003 0"
      rpy="6.0427E-17 -6.7283E-18 -4.0657E-34" />
    <parent
      link="finger_3_med_link" />
    <child
      link="finger_3_dist_link" />
    <axis
      xyz="0 0 1" />
    <limit
      lower="-0.785"
      upper="0"
      effort="0"
      velocity="0" />
<mimic joint="finger_3_med_joint" multiplier="0.3" offset="0.0"/>
  </joint>


  <!-- end of joint list -->




  <!-- ROS base_link to ABB World Coordinates transform -->
  <link name="base"/>
  <joint name="base_link-base" type="fixed">
    <origin rpy="0 0 0" xyz="0 0 0"/>
    <parent link="base_link"/>
    <child link="base"/>
  </joint>
</robot>

